Workbook

Sheet 平台分类颜色
A1: 平台 | B1: 标色分类
A2: 微店
A3: 小红书
A4: 抖店
A5: 淘宝
A6: 拼多多

Sheet 提现记录
A1: 店铺提现日期 | B1: Wawa小厨的店 | C1: wawa同人社的店 | D1: WAWA同人社 | E1: wawa同人社 | F1: wawa同人社 | G1: wawa同人社 | H1: Meow meow | I1: Meow meow | J1: Meow市集 | K1: Meow市集 | L1: Meow市集 | M1: MEOW市集 | N1: 甜心花栗 | O1: 小马娃社 | P1: 甜心花栗的店 | Q1: 也困 | R1: 也困微店 | S1: 海盐泡泡 | T1: 脑细胞仓库 | U1: 脑细胞仓库 | V1: 什么羊 | W1: 奶油兔司CreamyBunny | X1: 奶油兔司CreamyBunny | Y1: 海苔不睡 | Z1: 海苔不睡 | AA1: 来一口大米饭 | AB1: 来口大米饭 | AC1: 来口大米饭 | AD1: 来口大米饭 | AE1: 洋葱鼠鼠咪 | AF1: 猫猫布丁 | AG1: 猫屿物语 | AH1: 猫屿物语 | AI1: 猫屿物语 | AJ1: 猫屿物语 | AK1: 玻璃海 | AL1: 玻璃喵
A2: 平台 | B2: 小红书 | C2: 小红书 | D2: 微店 | E2: 拼多多 | F2: 抖店 | G2: 淘宝 | H2: 抖店 | I2: 小红书 | J2: 小红书 | K2: 抖店 | L2: 微店 | M2: 淘宝 | N2: 抖店 | O2: 微店 | P2: 小红书 | Q2: 小红书 | R2: 微店 | S2: 微店 | T2: 小红书 | U2: 微店 | V2: 微店 | W2: 微店 | X2: 小红书 | Y2: 小红书 | Z2: 抖店 | AA2: 微店 | AB2: 小红书 | AC2: 抖店 | AD2: 淘宝 | AE2: 小红书 | AF2: 微店 | AG2: 小红书 | AH2: 微店 | AI2: 拼多多 | AJ2: 淘宝 | AK2: 微店 | AL2: 微店
A3: 46143 | B3: 0 | C3: 0 | D3: 0 | E3: 0 | F3: 0 | G3: 0 | H3: 0 | I3: 0 | J3: 0 | K3: 0 | L3: 0 | M3: 0 | N3: 0 | O3: 0 | P3: 0 | Q3: 0 | R3: 0 | S3: 0 | T3: 0 | U3: 0 | V3: 0 | W3: 0 | X3: 0 | Y3: 0 | Z3: 0 | AA3: 0 | AB3: 0 | AC3: 0 | AD3: 0 | AE3: 0 | AF3: 0 | AG3: 0 | AH3: 0 | AI3: 0 | AJ3: 0 | AK3: 0 | AL3: 0
A4: 46144 | B4: 0 | C4: 0 | D4: 0 | E4: 0 | F4: 0 | G4: 0 | H4: 0 | I4: 0 | J4: 0 | K4: 0 | L4: 0 | M4: 0 | N4: 0 | O4: 0 | P4: 0 | Q4: 0 | R4: 0 | S4: 0 | T4: 0 | U4: 0 | V4: 0 | W4: 0 | X4: 0 | Y4: 0 | Z4: 0 | AA4: 0 | AB4: 0 | AC4: 0 | AD4: 0 | AE4: 0 | AF4: 0 | AG4: 0 | AH4: 0 | AI4: 0 | AJ4: 0 | AK4: 0 | AL4: 0
A5: 46145 | B5: 0 | C5: 0 | D5: 0 | E5: 0 | F5: 0 | G5: 0 | H5: 0 | I5: 0 | J5: 0 | K5: 0 | L5: 0 | M5: 0 | N5: 0 | O5: 0 | P5: 0 | Q5: 0 | R5: 0 | S5: 0 | T5: 0 | U5: 0 | V5: 0 | W5: 0 | X5: 0 | Y5: 0 | Z5: 0 | AA5: 0 | AB5: 0 | AC5: 0 | AD5: 0 | AE5: 0 | AF5: 0 | AG5: 0 | AH5: 0 | AI5: 0 | AJ5: 0 | AK5: 0 | AL5: 0
A6: 46146 | B6: 24930.63 | C6: 0 | D6: 0 | E6: 0 | F6: 0 | G6: 0 | H6: 0 | I6: 0 | J6: 0 | K6: 0 | L6: 0 | M6: 0 | N6: 0 | O6: 0 | P6: 0 | Q6: 0 | R6: 0 | S6: 0 | T6: 0 | U6: 0 | V6: 0 | W6: 0 | X6: 0 | Y6: 0 | Z6: 0 | AA6: 0 | AB6: 0 | AC6: 0 | AD6: 0 | AE6: 0 | AF6: 0 | AG6: 0 | AH6: 0 | AI6: 0 | AJ6: 0 | AK6: 0 | AL6: 0
A7: 46147 | B7: 0 | C7: 0 | D7: 0 | E7: 0 | F7: 0 | G7: 0 | H7: 0 | I7: 0 | J7: 0 | K7: 0 | L7: 0 | M7: 0 | N7: 0 | O7: 0 | P7: 0 | Q7: 0 | R7: 0 | S7: 0 | T7: 0 | U7: 0 | V7: 0 | W7: 0 | X7: 0 | Y7: 0 | Z7: 0 | AA7: 0 | AB7: 0 | AC7: 0 | AD7: 0 | AE7: 0 | AF7: 0 | AG7: 0 | AH7: 0 | AI7: 0 | AJ7: 0 | AK7: 0 | AL7: 0
A8: 46148 | B8: 0 | C8: 0 | D8: 0 | E8: 0 | F8: 0 | G8: 0 | H8: 0 | I8: 0 | J8: 0 | K8: 0 | L8: 0 | M8: 0 | N8: 0 | O8: 0 | P8: 0 | Q8: 0 | R8: 0 | S8: 0 | T8: 0 | U8: 0 | V8: 0 | W8: 0 | X8: 0 | Y8: 0 | Z8: 0 | AA8: 0 | AB8: 0 | AC8: 0 | AD8: 0 | AE8: 0 | AF8: 0 | AG8: 0 | AH8: 0 | AI8: 0 | AJ8: 0 | AK8: 0 | AL8: 0
A9: 46149 | B9: 0 | C9: 0 | D9: 0 | E9: 0 | F9: 122383.45 | G9: 0 | H9: 0 | I9: 0 | J9: 0 | K9: 0 | L9: 0 | M9: 0 | N9: 0 | O9: 0 | P9: 0 | Q9: 0 | R9: 0 | S9: 0 | T9: 0 | U9: 0 | V9: 0 | W9: 0 | X9: 0 | Y9: 0 | Z9: 0 | AA9: 0 | AB9: 0 | AC9: 0 | AD9: 0 | AE9: 0 | AF9: 0 | AG9: 0 | AH9: 0 | AI9: 0 | AJ9: 0 | AK9: 0 | AL9: 0
A10: 46150 | B10: 0 | C10: 0 | D10: 0 | E10: 0 | F10: 38376.98 | G10: 0 | H10: 0 | I10: 0 | J10: 0 | K10: 0 | L10: 0 | M10: 0 | N10: 0 | O10: 0 | P10: 0 | Q10: 0 | R10: 0 | S10: 0 | T10: 0 | U10: 0 | V10: 0 | W10: 0 | X10: 0 | Y10: 0 | Z10: 0 | AA10: 0 | AB10: 0 | AC10: 0 | AD10: 0 | AE10: 0 | AF10: 0 | AG10: 0 | AH10: 0 | AI10: 0 | AJ10: 0 | AK10: 0 | AL10: 0
A11: 46151 | B11: 0 | C11: 0 | D11: 0 | E11: 0 | F11: 0 | G11: 0 | H11: 0 | I11: 0 | J11: 0 | K11: 0 | L11: 0 | M11: 0 | N11: 8533.29 | O11: 0 | P11: 0 | Q11: 0 | R11: 0 | S11: 0 | T11: 0 | U11: 0 | V11: 0 | W11: 0 | X11: 0 | Y11: 0 | Z11: 0 | AA11: 0 | AB11: 0 | AC11: 0 | AD11: 0 | AE11: 0 | AF11: 0 | AG11: 0 | AH11: 0 | AI11: 0 | AJ11: 0 | AK11: 0 | AL11: 0
A12: 46152 | B12: 0 | C12: 0 | D12: 0 | E12: 0 | F12: 0 | G12: 0 | H12: 0 | I12: 0 | J12: 0 | K12: 0 | L12: 0 | M12: 0 | N12: 0 | O12: 0 | P12: 0 | Q12: 0 | R12: 0 | S12: 0 | T12: 0 | U12: 0 | V12: 0 | W12: 0 | X12: 0 | Y12: 0 | Z12: 0 | AA12: 0 | AB12: 0 | AC12: 0 | AD12: 0 | AE12: 0 | AF12: 0 | AG12: 0 | AH12: 0 | AI12: 0 | AJ12: 0 | AK12: 0 | AL12: 0
A13: 46153 | B13: 32465.7 | C13: 0 | D13: 0 | E13: 0 | F13: 0 | G13: 0 | H13: 0 | I13: 0 | J13: 0 | K13: 0 | L13: 41000 | M13: 0 | N13: 0 | O13: 0 | P13: 0 | Q13: 0 | R13: 0 | S13: 0 | T13: 0 | U13: 0 | V13: 0 | W13: 0 | X13: 0 | Y13: 0 | Z13: 0 | AA13: 0 | AB13: 0 | AC13: 0 | AD13: 0 | AE13: 0 | AF13: 0 | AG13: 0 | AH13: 0 | AI13: 0 | AJ13: 0 | AK13: 0 | AL13: 0
A14: 46154 | B14: 0 | C14: 0 | D14: 0 | E14: 0 | F14: 46461.96 | G14: 0 | H14: 0 | I14: 0 | J14: 0 | K14: 0 | L14: 0 | M14: 0 | N14: 0 | O14: 0 | P14: 0 | Q14: 0 | R14: 0 | S14: 0 | T14: 0 | U14: 0 | V14: 0 | W14: 0 | X14: 0 | Y14: 0 | Z14: 0 | AA14: 0 | AB14: 0 | AC14: 0 | AD14: 0 | AE14: 0 | AF14: 0 | AG14: 0 | AH14: 0 | AI14: 0 | AJ14: 0 | AK14: 0 | AL14: 0
... A26: 46166 | B26: 0 | C26: 0 | D26: 0 | E26: 0 | F26: 33675.1 | G26: 0 | H26: 0 | I26: 0 | J26: 0 | K26: 0 | L26: 0 | M26: 0 | N26: 0 | O26: 0 | P26: 0 | Q26: 0 | R26: 0 | S26: 0 | T26: 0 | U26: 0 | V26: 0 | W26: 0 | X26: 0 | Y26: 0 | Z26: 0 | AA26: 0 | AB26: 0 | AC26: 0 | AD26: 0 | AE26: 0 | AF26: 0 | AG26: 0 | AH26: 0 | AI26: 0 | AJ26: 0 | AK26: 0 | AL26: 0
A27: 46167 | B27: 50653.76 | C27: 0 | D27: 1021.33 | E27: 0 | F27: 9963.81 | G27: 0 | H27: 47088.5 | I27: 0 | J27: 156768.36 | K27: 41409.26 | L27: 9550.29 | M27: 0 | N27: 15972.17 | O27: ='日店铺可提现资金明细（可分配）'!P36 | P27: 276803.91 | Q27: 0 | R27: 475.03 | S27: 3511.78 | T27: 57536.83 | U27: ='日店铺可提现资金明细（可分配）'!V36 | V27: 0 | W27: 0 | X27: 0 | Y27: 0 | Z27: 0 | AA27: 0 | AB27: 0 | AC27: 0 | AD27: 0 | AE27: 0 | AF27: 0 | AG27: 0 | AH27: 0 | AI27: 0 | AJ27: 0 | AK27: 0 | AL27: 0
A28: 46168 | B28: 0 | C28: 0 | D28: 0 | E28: 0 | F28: 10379.32 | G28: 13306.3 | H28: 0 | I28: 0 | J28: 0 | K28: 0 | L28: 811.07 | M28: 0 | N28: 0 | O28: 0 | P28: 0 | Q28: 0 | R28: 0 | S28: 0 | T28: 0 | U28: 0 | V28: 0 | W28: 0 | X28: 0 | Y28: 0 | Z28: 0 | AA28: 0 | AB28: 0 | AC28: 0 | AD28: 0 | AE28: 0 | AF28: 0 | AG28: 0 | AH28: 0 | AI28: 0 | AJ28: 0 | AK28: 0 | AL28: 0
A29: 46169 | B29: 0 | C29: 0 | D29: 0 | E29: 0 | F29: 17052.52 | G29: 0 | H29: 0 | I29: 0 | J29: 0 | K29: 0 | L29: 0 | M29: 0 | N29: 0 | O29: 0 | P29: 0 | Q29: 0 | R29: 0 | S29: 0 | T29: 0 | U29: 0 | V29: 0 | W29: 0 | X29: 0 | Y29: 0 | Z29: 0 | AA29: 0 | AB29: 0 | AC29: 0 | AD29: 0 | AE29: 0 | AF29: 0 | AG29: 0 | AH29: 0 | AI29: 0 | AJ29: 0 | AK29: 0 | AL29: 0
A30: 46170 | B30: 0 | C30: 0 | D30: 0 | E30: 0 | F30: 0 | G30: 0 | H30: 14314.63 | I30: 0 | J30: 0 | K30: 0 | L30: 0 | M30: 0 | N30: 0 | O30: 0 | P30: 0 | Q30: 0 | R30: 0 | S30: 0 | T30: 0 | U30: 0 | V30: 0 | W30: 0 | X30: 0 | Y30: 0 | Z30: 0 | AA30: 0 | AB30: 0 | AC30: 0 | AD30: 0 | AE30: 0 | AF30: 0 | AG30: 0 | AH30: 0 | AI30: 0 | AJ30: 0 | AK30: 0 | AL30: 0
A31: 46171 | B31: 0 | C31: 0 | D31: 0 | E31: 0 | F31: 0 | G31: 0 | H31: 0 | I31: 0 | J31: 0 | K31: 0 | L31: 0 | M31: 0 | N31: 0 | O31: 0 | P31: 0 | Q31: 0 | R31: 0 | S31: 0 | T31: 0 | U31: 0 | V31: 0 | W31: 0 | X31: 0 | Y31: 0 | Z31: 0 | AA31: 0 | AB31: 0 | AC31: 0 | AD31: 0 | AE31: 0 | AF31: 0 | AG31: 0 | AH31: 0 | AI31: 0 | AJ31: 0 | AK31: 0 | AL31: 0
A32: 46172 | B32: 0 | C32: 0 | D32: 0 | E32: 0 | F32: 0 | G32: 0 | H32: 0 | I32: 0 | J32: 0 | K32: 0 | L32: 0 | M32: 0 | N32: 0 | O32: 0 | P32: 0 | Q32: 0 | R32: 0 | S32: 0 | T32: 0 | U32: 0 | V32: 0 | W32: 0 | X32: 0 | Y32: 0 | Z32: 0 | AA32: 0 | AB32: 0 | AC32: 0 | AD32: 0 | AE32: 0 | AF32: 0 | AG32: 0 | AH32: 0 | AI32: 0 | AJ32: 0 | AK32: 0 | AL32: 0
A33: 46173 | B33: 0 | C33: 0 | D33: 0 | E33: 0 | F33: 0 | G33: 0 | H33: 0 | I33: 0 | J33: 0 | K33: 0 | L33: 0 | M33: 0 | N33: 0 | O33: 0 | P33: 0 | Q33: 0 | R33: 0 | S33: 0 | T33: 0 | U33: 0 | V33: 0 | W33: 0 | X33: 0 | Y33: 0 | Z33: 0 | AA33: 0 | AB33: 0 | AC33: 0 | AD33: 0 | AE33: 0 | AF33: 0 | AG33: 0 | AH33: 0 | AI33: 0 | AJ33: 0 | AK33: 0 | AL33: 0
A34: 提现合计 | B34: =SUM(B3:B33) | C34: =SUM(C3:C33) | D34: =SUM(D3:D33) | E34: =SUM(E3:E33) | F34: =SUM(F3:F33) | G34: =SUM(G3:G33) | H34: =SUM(H3:H33) | I34: =SUM(I3:I33) | ... AL34: =SUM(AL3:AL33)
A35: 持卡人 | B35: 周振豪 | C35: 周振豪 | D35: 电子商务-企业 | F35: 电子商务-企业 | G35: 电子商务-企业 | H35: 喵鸣潮玩-企业 | I35: 杨玉英 | J35: 杨玉英 | K35: 绒绒岛潮玩 | L35: 杨玉英 | M35: 杨玉英 | N35: 电子商务-企业 | O35: 周振豪 | P35: 周振豪 | Q35: 三棉潮玩 | R35: 三棉潮玩 | S35: 周振豪 | T35: 杨丽燕 | U35: 周振豪 | V35: 郭海莹 | W35: 奶油兔 | X35: 奶油兔 | Y35: 王琳 | Z35: 王琳 | AA35: 萌造社 | AB35: 萌造社 | AC35: 萌造社 | AD35: 萌造社 | AE35: 王琴 | AF35: 杨玉英 | AG35: 电子商务-企业 | AH35: 周振民 | AI35: 周振豪 | AJ35: 电子商务-企业 | AL35: 王琳
A36: 银行 | B36: 工商银行(8818) | C36: 工商银行(8818) | D36: 基本户 | F36: 基本户 | G36: 基本户 | H36: 基本户 | I36: 邮政储蓄银行(0437） | J36: 邮政储蓄银行(0437） | K36: 基本户 | L36: 邮政储蓄银行(0437） | M36: 邮政储蓄银行(0437） | N36: 基本户 | O36: 建设银行(7260) | P36: 建设银行(7260) | Q36: 基本户（5634） | R36: 基本户（5634） | S36: 工商银行(8818) | T36: 农业银行（8379） | U36: 工商银行(8818) | V36: 中国银行(2440) | W36: 基本户 | X36: 基本户 | Y36: 招商银行（9493） | Z36: 招商银行（9493） | AA36: 基本户 | AB36: 基本户 | AC36: 基本户 | AD36: 基本户 | AE36: 建设银行（8426） | AG36: 基本户 | AH36: 工商银行(6496) | AI36: 工商银行(8818) | AJ36: 基本户 | AL36: 招商银行(9493)
B37: =B34='日店铺可提现资金明细（可分配）'!C36 | D37: =D34='日店铺可提现资金明细（可分配）'!E36 | F37: =F34='日店铺可提现资金明细（可分配）'!G36 | G37: =G34='日店铺可提现资金明细（可分配）'!H36 | H37: =H34='日店铺可提现资金明细（可分配）'!I36 | I37: =I34='日店铺可提现资金明细（可分配）'!J36 | J37: ='日店铺可提现资金明细（可分配）'!K36=J34 | K37: =K34='日店铺可提现资金明细（可分配）'!L36 | L37: =L34='日店铺可提现资金明细（可分配）'!M36 | N37: =N34='日店铺可提现资金明细（可分配）'!O36 | O37: =O34='日店铺可提现资金明细（可分配）'!P36 | P37: =P34='日店铺可提现资金明细（可分配）'!Q36 | Q37: =Q34='日店铺可提现资金明细（可分配）'!R36 | R37: =R34='日店铺可提现资金明细（可分配）'!S36 | S37: =S34='日店铺可提现资金明细（可分配）'!T36 | T37: =T34='日店铺可提现资金明细（可分配）'!U36 | U37: =U34='日店铺可提现资金明细（可分配）'!V36 | ... X37: =X34='日店铺可提现资金明细（可分配）'!Y36 | Z37: =Z34='日店铺可提现资金明细（可分配）'!AA36 | AA37: =AA34='日店铺可提现资金明细（可分配）'!AB36 | AC37: =AC34='日店铺可提现资金明细（可分配）'!AD36 | AF37: =AF34='日店铺可提现资金明细（可分配）'!AG36 | AG37: =AG34='日店铺可提现资金明细（可分配）'!Q36 | AH37: =AH34='日店铺可提现资金明细（可分配）'!AI36 | AK37: =AK34='日店铺可提现资金明细（可分配）'!AL36 | AL37: =AL34='日店铺可提现资金明细（可分配）'!AM36

Sheet 提现确认记录

Sheet 日店铺可提现资金明细（可分配）
A1: 店铺 日期 | B1: 汇总本日资金池 | C1: Wawa小厨的店 | D1: wawa同人社的店 | E1: WAWA同人社 | F1: wawa同人社 | G1: wawa同人社 | H1: wawa同人社 | I1: Meow meow | J1: Meow meow | K1: Meow市集 | L1: Meow市集 | M1: Meow市集 | N1: MEOW市集 | O1: 甜心花栗 | P1: 小马娃社 | Q1: 甜心花栗的店 | R1: 也困 | S1: 也困微店 | T1: 海盐泡泡 | U1: 脑细胞仓库 | V1: 脑细胞仓库 | W1: 什么羊 | X1: 奶油兔司CreamyBunny | Y1: 奶油兔司CreamyBunny | Z1: 海苔不睡 | AA1: 海苔不睡 | AB1: 来一口大米饭 | AC1: 来口大米饭 | AD1: 来口大米饭 | AE1: 来口大米饭 | AF1: 洋葱鼠鼠咪 | AG1: 猫猫布丁 | AH1: 猫屿物语 | AI1: 猫屿物语 | AJ1: 猫屿物语 | AK1: 猫屿物语 | AL1: 玻璃海 | AM1: 玻璃喵
A2: 各平台可提现金 | C2: 小红书 | D2: 小红书 | E2: 微店 | F2: 拼多多 | G2: 抖店 | H2: 淘宝 | I2: 抖店 | J2: 小红书 | K2: 小红书 | L2: 抖店 | M2: 微店 | N2: 淘宝 | O2: 抖店 | P2: 微店 | Q2: 小红书 | R2: 小红书 | S2: 微店 | T2: 微店 | U2: 小红书 | V2: 微店 | W2: 微店 | X2: 微店 | Y2: 小红书 | Z2: 小红书 | AA2: 抖店 | AB2: 微店 | AC2: 小红书 | AD2: 抖店 | AE2: 淘宝 | AF2: 小红书 | AG2: 微店 | AH2: 小红书 | AI2: 微店 | AJ2: 拼多多 | AK2: 淘宝 | AL2: 微店 | AM2: 微店
A3: 期初值 | B3: =SUM(C3:AM3)
A4: 46143 | B4: =SUM(C4:AM4) | J4: 391 | K4: 14314.3 | R4: 399.64 | U4: 849.87
A5: 46144 | B5: =SUM(C5:AM5) | J5: 863.11 | K5: -49.4 | R5: 85.49 | U5: 1476.09
A6: 46145 | B6: =SUM(C6:AM6) | J6: 513 | R6: 263.42 | U6: 2067.58
A7: 46146 | B7: =SUM(C7:AM7) | J7: 1033.6 | K7: 928.9 | R7: 4025.99 | U7: 1643.08
A8: 46147 | B8: =SUM(C8:AM8) | J8: 325 | K8: 10696.15 | R8: 216.71 | U8: 1302.17
A9: 46148 | B9: =SUM(C9:AM9) | J9: 1290.1 | K9: 2235.07 | R9: 256.47 | U9: 1028.79
A10: 46149 | B10: =SUM(C10:AM10) | J10: 8855.87 | K10: 3503.3 | R10: 434.4 | U10: 760.41 | AH10: 34.49
A11: 46150 | B11: =SUM(C11:AM11) | J11: 190.95 | K11: 10232.39 | R11: 309.15 | U11: 1469.09
A12: 46151 | B12: =SUM(C12:AM12) | J12: 265.05 | K12: 2533.3 | R12: 528.78 | U12: 1928.39
A13: 46152 | B13: =SUM(C13:AM13) | J13: 74 | K13: 3102.75 | R13: 742.49 | U13: 1743.47
A14: 46153 | B14: =SUM(C14:AM14) | J14: 130.15 | K14: 3415.1 | R14: 819.12 | U14: 1028.79
A15: 46154 | B15: =SUM(C15:AM15) | J15: 494 | K15: 7356.95 | R15: 403.58 | U15: 1162.98
A16: 46155 | B16: =SUM(C16:AM16) | J16: 172.9 | K16: 8046.85 | R16: 454.24 | U16: 760.41
A17: 46156 | B17: =SUM(C17:AM17) | J17: 191.6 | K17: 2774.31 | R17: 311.14 | U17: 1391.63
A18: 46157 | B18: =SUM(C18:AM18) | J18: 296.4 | K18: 2643.4 | R18: 1862.83 | U18: 894.6
A19: 46158 | B19: =SUM(C19:AM19) | J19: 200.45 | K19: 2496.4 | R19: 1903.57 | U19: 1366.9 | AH19: -0.3
A20: 46159 | B20: =SUM(C20:AM20) | J20: 463.75 | K20: 3181.05 | R20: 446.33 | U20: 805.14
A21: 46160 | B21: =SUM(C21:AM21) | J21: 228.95 | K21: 3745.7 | R21: 634.21 | U21: 2316.23
A22: 46161 | B22: =SUM(C22:AM22) | J22: 1254.95 | K22: 3670.2 | R22: 575.55 | U22: 1476.09
A23: 46162 | B23: =SUM(C23:AM23) | J23: -8392.59 | K23: 9658.2 | R23: 498.02 | U23: 1481.09
A24: 46163 | B24: =SUM(C24:AM24) | J24: 1987.49 | K24: 3817.95 | R24: 333.01 | U24: 1195.78
A25: 46164 | B25: =SUM(C25:AM25) | J25: 898.69 | K25: 12090.6 | R25: -5487.46 | U25: 1567.57 | AH25: -0.3
A26: 46165 | B26: =SUM(C26:AM26) | J26: 1251.2 | K26: 12493.25 | R26: 4381.67 | U26: 4891.57
A27: 46166 | B27: =SUM(C27:AM27) | J27: 869.47 | K27: 6689.65 | R27: 330.44 | U27: 1205.73
A28: 46167 | B28: =SUM(C28:AM28) | J28: 4288.82 | K28: -150960.21 | R28: 515.34 | U28: -56377.81
A29: 46168 | B29: =SUM(C29:AM29) | J29: 748.12 | K29: 2603.1 | R29: 510.69 | U29: 1020.87
A30: 46169 | J30: 3149.46 | K30: 3061.2 | R30: 509.91 | U30: 793.88
A31: 46170 | J31: 5407.69 | K31: -7276.1 | R31: 1890.5 | U31: 1517.9
A32: 46171 | J32: 1008.28 | K32: 2226.5 | R32: 680.44 | U32: 866.88 | AH32: -0.3
A33: 46172 | J33: 1010.91 | K33: 2919.95 | R33: 835.92 | U33: 942.48 | AH33: 47.4
A34: 46173 | J34: 981.68 | K34: 3082.75 | R34: 848.14 | U34: 1116.5
A35: 本月收入净值 | B35: =SUM(B4:B34) | C35: =SUM(C4:C34) | D35: =SUM(D4:D34) | E35: =SUM(E4:E34) | F35: =SUM(F4:F34) | G35: =SUM(G4:G34) | H35: =SUM(H4:H34) | I35: =SUM(I4:I34) | ... AM35: =SUM(AM4:AM34)
A36: 本月提现金额 | B36: =SUM(C36:AM36) | C36: =113883.14+50653.76 | D36: 180836.92 | E36: 13220.93 | G36: =提现记录!F34 | H36: =50082.04+13306.3 | I36: =提现记录!H34 | J36: 9869.95 | K36: =156768.36 | L36: 41409.26 | M36: =41000+12000+9550.29+811.07 | O36: 24505.46 | P36: 1537.8 | Q36: 276803.91 | R36: 5904.96 | S36: 5479.74 | T36: =31706.94+3511.78 | U36: =348.11+57188.72 | V36: 3065.59 | W36: 40000 | X36: 0 | Y36: 12368.17 | AB36: 0
A37: 本月资金冻结 | C37: 0 | H37: 0 | I37: 75662.91 | L37: 174975.26 | AA37: 43.7 | AB37: 0 | AF37: 10350.64 | AK37: 7.58
A38: 本月提现次数 | B38: =SUM(E38:AM38) | C38: 4 | D38: 7 | G38: 5 | I38: 0 | K38: 1 | M38: 1 | P38: 0 | Q38: 1 | U38: 1 | W38: 1 | X38: 0 | Y38: 1 | AB38: 0
A39: 持卡人 | C39: 周振豪 | D39: 周振豪 | E39: 电子商务-企业 | G39: 电子商务-企业 | H39: 电子商务-企业 | I39: 喵鸣潮玩-企业 | J39: 杨玉英 | K39: 杨玉英 | L39: 绒绒岛潮玩 | M39: 杨玉英 | N39: 杨玉英 | O39: 电子商务-企业 | P39: 周振豪 | Q39: 周振豪 | R39: 三棉潮玩 | S39: 三棉潮玩 | T39: 周振豪 | U39: 杨丽燕 | V39: 周振豪 | W39: 郭海莹 | X39: 奶油兔 | Y39: 奶油兔 | Z39: 王琳 | AA39: 王琳 | AB39: 萌造社 | AC39: 萌造社 | AD39: 萌造社 | AE39: 萌造社 | AF39: 王琴 | AG39: 杨玉英 | AH39: 电子商务-企业 | AI39: 周振民 | AJ39: 周振豪 | AK39: 电子商务-企业 | AM39: 王琳
A40: 银行卡 | C40: 工商银行(8818) | D40: 工商银行(8818) | E40: 基本户 | G40: 基本户 | H40: 基本户 | I40: 基本户 | J40: 邮政储蓄银行(0437） | K40: 邮政储蓄银行(0437） | L40: 基本户（5775） | M40: 邮政储蓄银行(0437） | N40: 邮政储蓄银行(0437） | O40: 基本户 | P40: 建设银行(7260) | Q40: 建设银行(7260) | R40: 基本户 | S40: 基本户 | T40: 工商银行(8818) | U40: 农业银行（8379） | V40: 工商银行(8818) | W40: 中国银行(2440) | X40: 基本户 | Y40: 基本户 | Z40: 招商银行（9493） | AA40: 招商银行（9493） | AB40: 基本户 | AC40: 基本户 | AD40: 基本户 | AE40: 基本户 | AF40: 建设银行（8426） | AH40: 基本户 | AI40: 工商银行(6496) | AJ40: 工商银行(8818) | AK40: 基本户 | AM40: 招商银行(9493)
...

Sheet 可提现银行卡收款
A1: =TODAY()
A2: 序号 | B2: 持卡人 | C2: 银行信息 | D2: 可提现金额 | E2: 备注
A3: 1 | B3: 周振豪 | C3: 工商银行(8818) | D3: ='日店铺可提现资金明细（可分配）'!C41+'日店铺可提现资金明细（可分配）'!D41+'日店铺可提现资金明细（可分配）'!S41+'日店铺可提现资金明细（可分配）'!T41+'日店铺可提现资金明细（可分配）'!V41+'日店铺可提现资金明细（可分配）'!AJ41
C4: 建设银行(7260) | D4: ='日店铺可提现资金明细（可分配）'!P41+'日店铺可提现资金明细（可分配）'!Q41
A5: 2 | B5: 杨玉英 | C5: 邮政储蓄银行(0437） | D5: ='日店铺可提现资金明细（可分配）'!J41+'日店铺可提现资金明细（可分配）'!K41+'日店铺可提现资金明细（可分配）'!M41+'日店铺可提现资金明细（可分配）'!N41+'日店铺可提现资金明细（可分配）'!AG41
A6: 3 | B6: 周景迁 | C6: 建设银行(8680) | D6: ='日店铺可提现资金明细（可分配）'!R41
A7: 4 | B7: 杨丽燕 | C7: 农业银行（8379） | D7: ='日店铺可提现资金明细（可分配）'!U41
A8: 5 | B8: 郭海莹 | C8: 中国银行(2440) | D8: ='日店铺可提现资金明细（可分配）'!W41
A9: 6 | B9: 王琳 | C9: 招商银行（9493） | D9: ='日店铺可提现资金明细（可分配）'!Z41+'日店铺可提现资金明细（可分配）'!AA41+'日店铺可提现资金明细（可分配）'!AM41
A10: 7 | B10: 周振民 | C10: 工商银行(6496) | D10: ='日店铺可提现资金明细（可分配）'!AI41
A11: 8 | B11: 王琴 | C11: 建设银行（8426） | D11: ='日店铺可提现资金明细（可分配）'!AF41
A12: 9 | B12: 珠海市喵范电子商务有限公司 | C12: 基本户 | D12: ='日店铺可提现资金明细（可分配）'!E41+'日店铺可提现资金明细（可分配）'!G41+'日店铺可提现资金明细（可分配）'!H41+'日店铺可提现资金明细（可分配）'!O41+'日店铺可提现资金明细（可分配）'!AH41+'日店铺可提现资金明细（可分配）'!AK41
A13: 10 | B13: 珠海市喵呜潮玩文化创意有限公司 | C13: 基本户 | D13: ='日店铺可提现资金明细（可分配）'!I41
A14: 11 | B14: 珠海市绒绒岛潮玩文化有限公司 | C14: 基本户 | D14: ='日店铺可提现资金明细（可分配）'!L41
A15: 12 | B15: 深圳市奶油免电子商务有限公司 | C15: 基本户 | D15: ='日店铺可提现资金明细（可分配）'!X41+'日店铺可提现资金明细（可分配）'!Y41 | E15: 未开通账号
A16: 合计 | D16: =SUM(D3:D15) | E16: =D16

Sheet 对公账号收款明细
A1: 公司名称 日期 | B1: 汇总本日余额 | C1: 珠海市喵趣文化创意有限公司 | D1: 珠海市喵范电子商务有限公司 | E1: 珠海市绒绒岛潮玩文化有限公司 | F1: 珠海市喵呜潮玩文化创意有限公司 | G1: 珠海市星序科技有限公司 | H1: 珠海市三棉潮玩文化有限公司 | I1: 深圳市萌造社文化创意有限公司
A2: 46143 | B2: =SUM(C2:I2)
A3: 46144 | B3: =SUM(C3:I3)
A4: 46145 | B4: =SUM(C4:I4)
A5: 46146 | B5: =SUM(C5:I5)
A6: 46147 | B6: =SUM(C6:I6)
A7: 46148 | B7: =SUM(C7:I7)
A8: 46149 | B8: =SUM(C8:I8)
A9: 46150 | B9: =SUM(C9:I9)
A10: 46151 | B10: =SUM(C10:I10)
A11: 46152 | B11: =SUM(C11:I11)
A12: 46153 | B12: =SUM(C12:I12)
A13: 46154 | B13: =SUM(C13:I13)
... A20: 46161 | B20: =SUM(C20:I20)
A21: 46162 | B21: =SUM(C21:I21) | C21: 565.75 | D21: =150395.07+80000-224791.86 | E21: 22.63 | F21: 0 | G21: 1872.9 | H21: 0 | I21: 0
A22: 46163 | B22: =SUM(C22:I22)
A23: 46164 | B23: =SUM(C23:I23)
A24: 46165 | B24: =SUM(C24:I24)
A25: 46166 | B25: =SUM(C25:I25)
A26: 46167 | B26: =SUM(C26:I26)
A27: 46168 | B27: =SUM(C27:I27)
A28: 46169 | B28: =SUM(C28:I28)
A29: 46170 | B29: =SUM(C29:I29)
A30: 46171 | B30: =SUM(C30:I30)
A31: 46172 | B31: =SUM(C31:I31)
A32: 46173 | B32: =SUM(C32:I32)
B33: =SUM(B21:B32) | C33: =SUM(C21:C32) | D33: =SUM(D21:D32) | E33: =SUM(E21:E32) | F33: =SUM(F21:F32) | G33: =SUM(G21:G32) | H33: =SUM(H21:H32) | I33: =SUM(I21:I32)

Sheet 汇总列示
A1: =TODAY()
A2: 分类 | B2: 账号信息 | C2: 银行信息 | D2: 可提现金额 | E2: 备注
A3: 平台 | B3: 周振豪 | C3: 工商银行(8818) | D3: ='日店铺可提现资金明细（可分配）'!C41+'日店铺可提现资金明细（可分配）'!D41+'日店铺可提现资金明细（可分配）'!S41+'日店铺可提现资金明细（可分配）'!T41+'日店铺可提现资金明细（可分配）'!V41+'日店铺可提现资金明细（可分配）'!AJ41
A4: 平台 | C4: 建设银行(7260) | D4: ='日店铺可提现资金明细（可分配）'!P41+'日店铺可提现资金明细（可分配）'!Q41
A5: 平台 | B5: 杨玉英 | C5: 邮政储蓄银行(0437） | D5: ='日店铺可提现资金明细（可分配）'!J41+'日店铺可提现资金明细（可分配）'!K41+'日店铺可提现资金明细（可分配）'!M41+'日店铺可提现资金明细（可分配）'!N41+'日店铺可提现资金明细（可分配）'!AG41
A6: 平台 | B6: 周景迁 | C6: 建设银行(8680) | D6: ='日店铺可提现资金明细（可分配）'!R41
A7: 平台 | B7: 杨丽燕 | C7: 农业银行（8379） | D7: ='日店铺可提现资金明细（可分配）'!U41
A8: 平台 | B8: 郭海莹 | C8: 中国银行(2440) | D8: ='日店铺可提现资金明细（可分配）'!W41
A9: 平台 | B9: 王琳 | C9: 招商银行（9493） | D9: ='日店铺可提现资金明细（可分配）'!Z41+'日店铺可提现资金明细（可分配）'!AA41+'日店铺可提现资金明细（可分配）'!AM41
A10: 平台 | B10: 周振民 | C10: 工商银行(6496) | D10: ='日店铺可提现资金明细（可分配）'!AI41
A11: 平台 | B11: 王琴 | C11: 建设银行（8426） | D11: ='日店铺可提现资金明细（可分配）'!AF41
A12: 平台 | B12: 珠海市喵范电子商务有限公司 | C12: 基本户 | D12: ='日店铺可提现资金明细（可分配）'!E41+'日店铺可提现资金明细（可分配）'!G41+'日店铺可提现资金明细（可分配）'!H41+'日店铺可提现资金明细（可分配）'!O41+'日店铺可提现资金明细（可分配）'!AH41+'日店铺可提现资金明细（可分配）'!AK41
A13: 平台 | B13: 珠海市喵呜潮玩文化创意有限公司 | C13: 基本户 | D13: ='日店铺可提现资金明细（可分配）'!I41
A14: 平台 | B14: 珠海市绒绒岛潮玩文化有限公司 | C14: 基本户 | D14: ='日店铺可提现资金明细（可分配）'!L41
A15: 平台 | B15: 深圳市奶油免电子商务有限公司 | C15: 基本户 | D15: ='日店铺可提现资金明细（可分配）'!X41+'日店铺可提现资金明细（可分配）'!Y41 | E15: 未开通账号
A16: 基本户 | B16: 珠海市喵趣文化创意有限公司 | C16: 公户 | D16: =对公账号收款明细!C33
A17: 基本户 | B17: 珠海市喵范电子商务有限公司 | C17: 公户 | D17: =对公账号收款明细!D33
A18: 基本户 | B18: 珠海市绒绒岛潮玩文化有限公司 | C18: 公户 | D18: =对公账号收款明细!E33
A19: 基本户 | B19: 珠海市喵呜潮玩文化创意有限公司 | C19: 公户 | D19: =对公账号收款明细!F33
A20: 基本户 | B20: 珠海市星序科技有限公司 | C20: 公户 | D20: =对公账号收款明细!G33
A21: 基本户 | B21: 珠海市三棉潮玩文化有限公司 | C21: 公户 | D21: =对公账号收款明细!H33
A22: 基本户 | B22: 深圳市萌造社文化创意有限公司 | C22: 公户 | D22: =对公账号收款明细!I33
D23: =SUM(D3:D22) | E23: =D23
B25: 分类 | C25: 求和项:可提现金额
B26: 基本户 | C26: 8064.49
B27: 平台 | C27: 886906.53
B28: 总计 | C28: 894971.02
